Ожидаемый ответ:

Функция def rename_files найдена в файле __init__.py

Ошибка:

Traceback (most recent call last):
  File "ZQCDW95MFBUL36GZ2YIS.py", line 10, in <module>
    with open("__init__.py", "r") as init_file:
FileNotFoundError: [Errno 2] No such file or directory: '__init__.py'